<mujoco model="humanoid">
    <compiler angle="degree" inertiafromgeom="true"/>
    <default>
        <joint armature="1" damping="1" limited="true"/>
        <geom conaffinity="1" condim="1" contype="1" margin="0.001" material="geom" rgba="0.8 0.6 .4 1"/>
        <motor ctrllimited="true" ctrlrange="-.4 .4"/>
    </default>
    <option integrator="RK4" iterations="50" solver="PGS" timestep="0.003">
        <!-- <flags solverstat="enable" energy="enable"/>-->
    </option>
    <size nkey="5" nuser_geom="1"/>
    <visual>
        <map fogend="5" fogstart="3"/>
    </visual>
    <asset>
        <texture builtin="gradient" height="100" rgb1=".4 .5 .6" rgb2="0 0 0" type="skybox" width="100"/>
        <!-- <texture builtin="gradient" height="100" rgb1="1 1 1" rgb2="0 0 0" type="skybox" width="100"/>-->
        <texture builtin="flat" height="1278" mark="cross" markrgb="1 1 1" name="texgeom" random="0.01" rgb1="0.8 0.6 0.4" rgb2="0.8 0.6 0.4" type="cube" width="127"/>
        <texture builtin="checker" height="100" name="texplane" rgb1="0 0 0" rgb2="0.8 0.8 0.8" type="2d" width="100"/>
        <material name="MatPlane" reflectance="0.5" shininess="1" specular="1" texrepeat="60 60" texture="texplane"/>
        <material name="geom" texture="texgeom" texuniform="true"/>
    </asset>
    <worldbody>
        <light cutoff="100" diffuse="1 1 1" dir="-0 0 -1.3" directional="true" exponent="1" pos="0 0 1.3" specular=".1 .1 .1"/>
        <geom condim="3" friction="1 .1 .1" material="MatPlane" name="floor" pos="0 0 0" rgba="0.8 0.9 0.8 1" size="20 20 0.125" type="plane"/>
        <!-- <geom condim="3" material="MatPlane" name="floor" pos="0 0 0" size="10 10 0.125" type="plane"/>-->
        <body name="root" pos="0 0 1">
            <camera name="track" mode="trackcom" pos="0 -4 1" xyaxes="1 0 0 0 0 1"/>
            <geom name="root" pos="0 0 0.07" size=".09" type="sphere"/>
            <joint armature="0" damping="0" limited="false" name="root" pos="0 0 0" stiffness="0" type="free"/>
            <body name="joint_waist" pos="0 0 0.205">
                <geom name="joint_waist" pos="0 0 0" size="0.07" type="sphere"/>
            </body>
            <body name="chest" pos="0 0 0.236151">
                <geom name="chest" pos="0 0 0.12" size=".11" type="sphere"/>
                <joint armature="0.02" axis="1 0 0" damping="5" name="chest_x" pos="0 0 0" range="-68.75 68.75" stiffness="10" type="hinge"/>
                <joint armature="0.02" axis="0 1 0" damping="5" name="chest_y" pos="0 0 0" range="-68.75 68.75" stiffness="10" type="hinge"/>
                <joint armature="0.02" axis="0 0 1" damping="5" name="chest_z" pos="0 0 0" range="-68.75 68.75" stiffness="20" type="hinge"/>
                <body name="neck" pos="0 0 0.223894">
                    <geom name="neck" pos="0 0 0.175" size=".1025" type="sphere"/>
                    <joint armature="0.02" axis="1 0 0" damping="5" name="neck_x" pos="0 0 0" range="-57.3 57.3" stiffness="10" type="hinge"/>
                    <joint armature="0.02" axis="0 1 0" damping="5" name="neck_y" pos="0 0 0" range="-57.3 57.3" stiffness="10" type="hinge"/>
                    <joint armature="0.02" axis="0 0 1" damping="5" name="neck_z" pos="0 0 0" range="-57.3 57.3" stiffness="20" type="hinge"/>
                    <body name="joint_neck" pos="0 0 0.02">
                        <geom name="joint_neck" pos="0 0 0" size="0.04" type="sphere"/>
                    </body>
                </body>
                <body name="right_clavicle" pos="-0.011 -0.07 0.24">
                    <geom fromto="0 0 0 0 -0.05 0" name="right_clavicle" size="0.045" type="capsule"/>
                </body>
                <body name="right_shoulder" pos="-0.02405 -0.18311 0.2435">
                    <geom fromto="0 0 -0.05 0 0 -0.23" name="right_shoulder" size="0.045" type="capsule"/>
                    <joint armature="0.02" axis="1 0 0" damping="5" name="right_shoulder_x" pos="0 0 0" range="-180 28.65" stiffness="10" type="hinge"/>
                    <joint armature="0.02" axis="0 1 0" damping="5" name="right_shoulder_y" pos="0 0 0" range="-85.94 85.94" stiffness="10" type="hinge"/>
                    <joint armature="0.02" axis="0 0 1" damping="5" name="right_shoulder_z" pos="0 0 0" range="-40.11 180" stiffness="20" type="hinge"/>
                    <body name="joint_right_shoulder" pos="0 0 0">
                        <geom name="joint_right_shoulder" pos="0 0 0" size="0.04" type="sphere"/>
                    </body>
                    <body name="right_elbow" pos="0 0 -0.274788">
                        <geom fromto="0 0 -0.0525 0 0 -0.1875" name="right_elbow" size="0.04" type="capsule"/>
                        <joint armature="0" damping="0" limited="true" axis="0 1 0" name="right_elbow" pos="0 0 0" range="-150 0" stiffness="0" type="hinge"/>
                        <body name="joint_right_elbow" pos="0 0 0">
                            <geom name="joint_right_elbow" pos="0 0 0" size="0.03" type="sphere"/>
                        </body>
                        <body name="right_wrist" pos="0 0 -0.258947">
                            <geom name="right_wrist" pos="0 0 0" size="0.04" type="sphere"/>
                        </body>
                    </body>
                </body>
                <body name="left_clavicle" pos="-0.011 0.07 0.24">
                    <geom fromto="0 0 0 0 0.05 0" name="left_clavicle" size="0.045" type="capsule"/>
                </body>
                <body name="left_shoulder" pos="-0.02405 0.18311 0.2435">
                    <geom fromto="0 0 -0.05 0 0 -0.23" name="left_shoulder" size="0.045" type="capsule"/>
                    <joint armature="0.02" axis="1 0 0" damping="5" name="left_shoulder_x" pos="0 0 0" range="-28.65 180" stiffness="10" type="hinge"/>
                    <joint armature="0.02" axis="0 1 0" damping="5" name="left_shoulder_y" pos="0 0 0" range="-85.94 85.94" stiffness="10" type="hinge"/>
                    <joint armature="0.02" axis="0 0 1" damping="5" name="left_shoulder_z" pos="0 0 0" range="-40.11 180" stiffness="20" type="hinge"/>
                    <body name="joint_left_shoulder" pos="0 0 0">
                        <geom name="joint_left_shoulder" pos="0 0 0" size="0.04" type="sphere"/>
                    </body>
                    <body name="left_elbow" pos="0 0 -0.274788">
                        <geom fromto="0 0 -0.0525 0 0 -0.1875" name="left_elbow" size="0.04" type="capsule"/>
                        <joint armature="0" damping="0" limited="true" axis="0 1 0" name="left_elbow" pos="0 0 0" range="-150 0" stiffness="0" type="hinge"/>
                        <body name="joint_left_elbow" pos="0 0 0">
                            <geom name="joint_left_elbow" pos="0 0 0" size="0.03" type="sphere"/>
                        </body>
                        <body name="left_wrist" pos="0 0 -0.258947">
                            <geom name="left_wrist" pos="0 0 0" size="0.04" type="sphere"/>
                        </body>
                    </body>
                </body>
            </body>
            <body name="right_hip" pos="0 -0.084887 0">
                <geom fromto="0 0 -0.06 0 0 -0.36" name="right_hip" size="0.055" type="capsule"/>
                <joint armature="0.02" axis="1 0 0" damping="5" name="right_hip_x" pos="0 0 0" range="-68.75 68.75" stiffness="10" type="hinge"/>
                <joint armature="0.02" axis="0 1 0" damping="5" name="right_hip_y" pos="0 0 0" range="-57.3 57.3" stiffness="10" type="hinge"/>
                <joint armature="0.02" axis="0 0 1" damping="5" name="right_hip_z" pos="0 0 0" range="-90 147.25" stiffness="20" type="hinge"/>
                <body name="joint_right_hip" pos="0 0 0">
                    <geom name="joint_right_hip" pos="0 0 0" size="0.045" type="sphere"/>
                </body>
                <body name="right_knee" pos="0 0 -0.421546">
                    <geom fromto="0 0 -0.045 0 0 -0.355" name="right_knee" size="0.05" type="capsule"/>
                    <joint armature="0" damping="0" limited="true" axis="0 1 0" name="right_knee" pos="0 0 0" range="0 150" stiffness="0" type="hinge"/>
                    <body name="joint_right_knee" pos="0 0 0">
                        <geom name="joint_right_knee" pos="0 0 0" size="0.035" type="sphere"/>
                    </body>
                    <body name="right_ankle" pos="0 0 -0.40987">
                        <body name="joint_right_ankle" pos="0 0 0">
                            <geom name="joint_right_ankle" pos="0 0 0" size="0.04" type="sphere"/>
                        </body>
                        <geom name="right_ankle" pos="0.045 0 -0.0225" size="0.088 0.045 0.027" type="box"/>
                        <joint armature="0.02" axis="1 0 0" damping="5" name="right_ankle_x" pos="0 0 0" range="-57.3 57.3" stiffness="10" type="hinge"/>
                        <joint armature="0.02" axis="0 1 0" damping="5" name="right_ankle_y" pos="0 0 0" range="-57.3 57.3" stiffness="10" type="hinge"/>
                        <joint armature="0.02" axis="0 0 1" damping="5" name="right_ankle_z" pos="0 0 0" range="-90 90" stiffness="20" type="hinge"/>
                    </body>
                </body>
            </body>
            <body name="left_hip" pos="0 0.084887 0">
                <geom fromto="0 0 -0.06 0 0 -0.36" name="left_hip" size="0.055" type="capsule"/>
                <joint armature="0.02" axis="1 0 0" damping="5" name="left_hip_x" pos="0 0 0" range="-68.75 68.75" stiffness="10" type="hinge"/>
                <joint armature="0.02" axis="0 1 0" damping="5" name="left_hip_y" pos="0 0 0" range="-57.3 57.3" stiffness="10" type="hinge"/>
                <joint armature="0.02" axis="0 0 1" damping="5" name="left_hip_z" pos="0 0 0" range="-90 147.25" stiffness="20" type="hinge"/>
                <body name="joint_left_hip" pos="0 0 0">
                    <geom name="joint_left_hip" pos="0 0 0" size="0.045" type="sphere"/>
                </body>
                <body name="left_knee" pos="0 0 -0.421546">
                    <geom fromto="0 0 -0.045 0 0 -0.355" name="left_knee" size="0.05" type="capsule"/>
                    <joint armature="0" damping="0" limited="true" axis="0 1 0" name="left_knee" pos="0 0 0" range="0 150" stiffness="0" type="hinge"/>
                    <body name="joint_left_knee" pos="0 0 0">
                        <geom name="joint_left_knee" pos="0 0 0" size="0.035" type="sphere"/>
                    </body>
                    <body name="left_ankle" pos="0 0 -0.40987">
                        <geom name="left_ankle" pos="0.045 0 -0.0225" size="0.088 0.045 0.027" type="box"/>
                        <joint armature="0.02" axis="1 0 0" damping="5" name="left_ankle_x" pos="0 0 0" range="-57.3 57.3" stiffness="10" type="hinge"/>
                        <joint armature="0.02" axis="0 1 0" damping="5" name="left_ankle_y" pos="0 0 0" range="-57.3 57.3" stiffness="10" type="hinge"/>
                        <joint armature="0.02" axis="0 0 1" damping="5" name="left_ankle_z" pos="0 0 0" range="-90 90" stiffness="20" type="hinge"/>
                        <body name="joint_left_ankle" pos="0 0 0">
                            <geom name="joint_left_ankle" pos="0 0 0" size="0.04" type="sphere"/>
                        </body>
                    </body>
                </body>
            </body>
        </body>
        <!--
        <body name="torso" pos="0 0 1.4">
            <camera name="track" mode="trackcom" pos="0 -4 0" xyaxes="1 0 0 0 0 1"/>
            <joint armature="0" damping="0" limited="false" name="root" pos="0 0 0" stiffness="0" type="free"/>
            <geom fromto="0 -.07 0 0 .07 0" name="torso1" size="0.07" type="capsule"/>
            <geom name="head" pos="0 0 .19" size=".09" type="sphere" user="258"/>
            <geom fromto="-.01 -.06 -.12 -.01 .06 -.12" name="uwaist" size="0.06" type="capsule"/>
            <body name="lwaist" pos="-.01 0 -0.260" quat="1.000 0 -0.002 0">
                <geom fromto="0 -.06 0 0 .06 0" name="lwaist" size="0.06" type="capsule"/>
                <joint armature="0.02" axis="0 0 1" damping="5" name="abdomen_z" pos="0 0 0.065" range="-45 45" stiffness="20" type="hinge"/>
                <joint armature="0.02" axis="0 1 0" damping="5" name="abdomen_y" pos="0 0 0.065" range="-75 30" stiffness="10" type="hinge"/>
                <body name="pelvis" pos="0 0 -0.165" quat="1.000 0 -0.002 0">
                    <joint armature="0.02" axis="1 0 0" damping="5" name="abdomen_x" pos="0 0 0.1" range="-35 35" stiffness="10" type="hinge"/>
                    <geom fromto="-.02 -.07 0 -.02 .07 0" name="butt" size="0.09" type="capsule"/>
                    <body name="right_thigh" pos="0 -0.1 -0.04">
                        <joint armature="0.01" axis="1 0 0" damping="5" name="right_hip_x" pos="0 0 0" range="-25 5" stiffness="10" type="hinge"/>
                        <joint armature="0.01" axis="0 0 1" damping="5" name="right_hip_z" pos="0 0 0" range="-60 35" stiffness="10" type="hinge"/>
                        <joint armature="0.0080" axis="0 1 0" damping="5" name="right_hip_y" pos="0 0 0" range="-110 20" stiffness="20" type="hinge"/>
                        <geom fromto="0 0 0 0 0.01 -.34" name="right_thigh1" size="0.06" type="capsule"/>
                        <body name="right_shin" pos="0 0.01 -0.403">
                            <joint armature="0.0060" axis="0 -1 0" name="right_knee" pos="0 0 .02" range="-160 -2" type="hinge"/>
                            <geom fromto="0 0 0 0 0 -.3" name="right_shin1" size="0.049" type="capsule"/>
                            <body name="right_foot" pos="0 0 -0.45">
                                <geom name="right_foot" pos="0 0 0.1" size="0.075" type="sphere" user="0"/>
                            </body>
                        </body>
                    </body>
                    <body name="left_thigh" pos="0 0.1 -0.04">
                        <joint armature="0.01" axis="-1 0 0" damping="5" name="left_hip_x" pos="0 0 0" range="-25 5" stiffness="10" type="hinge"/>
                        <joint armature="0.01" axis="0 0 -1" damping="5" name="left_hip_z" pos="0 0 0" range="-60 35" stiffness="10" type="hinge"/>
                        <joint armature="0.01" axis="0 1 0" damping="5" name="left_hip_y" pos="0 0 0" range="-120 20" stiffness="20" type="hinge"/>
                        <geom fromto="0 0 0 0 -0.01 -.34" name="left_thigh1" size="0.06" type="capsule"/>
                        <body name="left_shin" pos="0 -0.01 -0.403">
                            <joint armature="0.0060" axis="0 -1 0" name="left_knee" pos="0 0 .02" range="-160 -2" stiffness="1" type="hinge"/>
                            <geom fromto="0 0 0 0 0 -.3" name="left_shin1" size="0.049" type="capsule"/>
                            <body name="left_foot" pos="0 0 -0.45">
                                <geom name="left_foot" type="sphere" size="0.075" pos="0 0 0.1" user="0" />
                            </body>
                        </body>
                    </body>
                </body>
            </body>
            <body name="right_upper_arm" pos="0 -0.17 0.06">
                <joint armature="0.0068" axis="2 1 1" name="right_shoulder1" pos="0 0 0" range="-85 60" stiffness="1" type="hinge"/>
                <joint armature="0.0051" axis="0 -1 1" name="right_shoulder2" pos="0 0 0" range="-85 60" stiffness="1" type="hinge"/>
                <geom fromto="0 0 0 .16 -.16 -.16" name="right_uarm1" size="0.04 0.16" type="capsule"/>
                <body name="right_lower_arm" pos=".18 -.18 -.18">
                    <joint armature="0.0028" axis="0 -1 1" name="right_elbow" pos="0 0 0" range="-90 50" stiffness="0" type="hinge"/>
                    <geom fromto="0.01 0.01 0.01 .17 .17 .17" name="right_larm" size="0.031" type="capsule"/>
                    <geom name="right_hand" pos=".18 .18 .18" size="0.04" type="sphere"/>
                    <camera pos="0 0 0"/>
                </body>
            </body>
            <body name="left_upper_arm" pos="0 0.17 0.06">
                <joint armature="0.0068" axis="2 -1 1" name="left_shoulder1" pos="0 0 0" range="-60 85" stiffness="1" type="hinge"/>
                <joint armature="0.0051" axis="0 1 1" name="left_shoulder2" pos="0 0 0" range="-60 85" stiffness="1" type="hinge"/>
                <geom fromto="0 0 0 .16 .16 -.16" name="left_uarm1" size="0.04 0.16" type="capsule"/>
                <body name="left_lower_arm" pos=".18 .18 -.18">
                    <joint armature="0.0028" axis="0 -1 -1" name="left_elbow" pos="0 0 0" range="-90 50" stiffness="0" type="hinge"/>
                    <geom fromto="0.01 -0.01 0.01 .17 -.17 .17" name="left_larm" size="0.031" type="capsule"/>
                    <geom name="left_hand" pos=".18 -.18 .18" size="0.04" type="sphere"/>
                </body>
            </body>
        </body>
        -->
    </worldbody>
    <!--
    <tendon>
        <fixed name="left_hipknee">
            <joint coef="-1" joint="left_hip_y"/>
            <joint coef="1" joint="left_knee"/>
        </fixed>
        <fixed name="right_hipknee">
            <joint coef="-1" joint="right_hip_y"/>
            <joint coef="1" joint="right_knee"/>
        </fixed>
    </tendon>
    -->

    <actuator>
        <motor gear="100" joint="chest_x" name="chest_x"/>
        <motor gear="100" joint="chest_y" name="chest_y"/>
        <motor gear="100" joint="chest_z" name="chest_z"/>

        <motor gear="100" joint="neck_x" name="neck_x"/>
        <motor gear="100" joint="neck_y" name="neck_y"/>
        <motor gear="100" joint="neck_z" name="neck_z"/>

        <motor gear="25" joint="right_shoulder_x" name="right_shoulder_x"/>
        <motor gear="25" joint="right_shoulder_y" name="right_shoulder_y"/>
        <motor gear="25" joint="right_shoulder_z" name="right_shoulder_z"/>

        <motor gear="25" joint="right_elbow" name="right_elbow"/>

        <motor gear="25" joint="left_shoulder_x" name="left_shoulder_x"/>
        <motor gear="25" joint="left_shoulder_y" name="left_shoulder_y"/>
        <motor gear="25" joint="left_shoulder_z" name="left_shoulder_z"/>

        <motor gear="25" joint="left_elbow" name="left_elbow"/>

        <motor gear="100" joint="right_hip_x" name="right_hip_x"/>
        <motor gear="300" joint="right_hip_y" name="right_hip_y"/>
        <motor gear="100" joint="right_hip_z" name="right_hip_z"/>

        <motor gear="200" joint="right_knee" name="right_knee"/>

        <motor gear="100" joint="right_ankle_x" name="right_ankle_x"/>
        <motor gear="100" joint="right_ankle_y" name="right_ankle_y"/>
        <motor gear="100" joint="right_ankle_z" name="right_ankle_z"/>

        <motor gear="100" joint="left_hip_x" name="left_hip_x"/>
        <motor gear="300" joint="left_hip_y" name="left_hip_y"/>
        <motor gear="100" joint="left_hip_z" name="left_hip_z"/>

        <motor gear="200" joint="left_knee" name="left_knee"/>

        <motor gear="100" joint="left_ankle_x" name="left_ankle_x"/>
        <motor gear="100" joint="left_ankle_y" name="left_ankle_y"/>
        <motor gear="100" joint="left_ankle_z" name="left_ankle_z"/>
    </actuator>
</mujoco>
